<?xml version="1.0" ?>
<!-- =================================================================================== -->
<!-- |    This document was autogenerated by xacro from variable_tilt_hexacopter.urdf.xacro | -->
<!-- |    EDITING THIS FILE BY HAND IS NOT RECOMMENDED                                 | -->
<!-- =================================================================================== -->
<robot name="variable_tilt_hexacopter">
  <!-- ======================
       0. Properties
  ====================== -->
  <!-- ======================
       1. Macros
  ====================== -->
  <!-- ======================
       2. Link Definitions
  ====================== -->
  <!-- Dummy Root -->
  <link name="base_dummy"/>
  <joint name="joint_base_dummy_to_base" type="fixed">
    <parent link="base_dummy"/>
    <child link="base"/>
    <origin xyz="0 0 0"/>
  </joint>
  <!-- Base -->
  <link name="base">
    <inertial>
      <mass value="1.564"/>
      <origin xyz="0 0 0"/>
      <inertia ixx="0.00229686" ixy="0" ixz="0" iyy="0.00229686" iyz="0" izz="0.00394206"/>
    </inertial>
    <visual>
      <geometry>
        <cylinder length="0.05" radius="0.071"/>
      </geometry>
    </visual>
    <collision>
      <geometry>
        <cylinder length="0.05" radius="0.071"/>
      </geometry>
    </collision>
    <sensor name="imu_sensor" type="imu">
      <always_on>true</always_on>
      <update_rate>100.0</update_rate>
      <pose>0 0 0 0 0 0</pose>
      <topic>/model/variable_tilt_hexacopter/imu</topic>
      <imu>
        <angular_velocity>
          <x>
            <noise type="gaussian">
              <mean>0</mean>
              <stddev>0.009</stddev>
              <bias_mean>0.00075</bias_mean>
              <bias_stddev>0.005</bias_stddev>
              <dynamic_bias_stddev>0.00002</dynamic_bias_stddev>
              <dynamic_bias_correlation_time>400.0</dynamic_bias_correlation_time>
              <precision>0.00025</precision>
            </noise>
          </x>
          <y>
            <noise type="gaussian">
              <mean>0</mean>
              <stddev>0.009</stddev>
              <bias_mean>0.00075</bias_mean>
              <bias_stddev>0.005</bias_stddev>
              <dynamic_bias_stddev>0.00002</dynamic_bias_stddev>
              <dynamic_bias_correlation_time>400.0</dynamic_bias_correlation_time>
              <precision>0.00025</precision>
            </noise>
          </y>
          <z>
            <noise type="gaussian">
              <mean>0</mean>
              <stddev>0.009</stddev>
              <bias_mean>0.00075</bias_mean>
              <bias_stddev>0.005</bias_stddev>
              <dynamic_bias_stddev>0.00002</dynamic_bias_stddev>
              <dynamic_bias_correlation_time>400.0</dynamic_bias_correlation_time>
              <precision>0.00025</precision>
            </noise>
          </z>
        </angular_velocity>
        <linear_acceleration>
          <x>
            <noise type="gaussian">
              <mean>0</mean>
              <stddev>0.021</stddev>
              <bias_mean>0.05</bias_mean>
              <bias_stddev>0.0075</bias_stddev>
              <dynamic_bias_stddev>0.000375</dynamic_bias_stddev>
              <dynamic_bias_correlation_time>175.0</dynamic_bias_correlation_time>
              <precision>0.005</precision>
            </noise>
          </x>
          <y>
            <noise type="gaussian">
              <mean>0</mean>
              <stddev>0.021</stddev>
              <bias_mean>0.05</bias_mean>
              <bias_stddev>0.0075</bias_stddev>
              <dynamic_bias_stddev>0.000375</dynamic_bias_stddev>
              <dynamic_bias_correlation_time>175.0</dynamic_bias_correlation_time>
              <precision>0.005</precision>
            </noise>
          </y>
          <z>
            <noise type="gaussian">
              <mean>0</mean>
              <stddev>0.021</stddev>
              <bias_mean>0.05</bias_mean>
              <bias_stddev>0.0075</bias_stddev>
              <dynamic_bias_stddev>0.000375</dynamic_bias_stddev>
              <dynamic_bias_correlation_time>175.0</dynamic_bias_correlation_time>
              <precision>0.005</precision>
            </noise>
          </z>
        </linear_acceleration>
        <orientation>
          <noise type="gaussian">
            <mean>0</mean>
            <stddev>0.001</stddev>
            <!-- Small noise on fused orientation -->
          </noise>
        </orientation>
      </imu>
      <plugin filename="ignition-gazebo-imu-system" name="ignition::gazebo::systems::Imu"/>
    </sensor>
  </link>
  <!-- Camera Link -->
  <link name="camera_link">
    <inertial>
      <pose>0.0 0.0 0.0 0 0 0</pose>
      <mass value="0.050"/>
      <inertia ixx="0.00004" ixy="0" ixz="0" iyy="0.00004" iyz="0" izz="0.00004"/>
    </inertial>
    <visual name="mono_cam/visual/housing">
      <geometry>
        <box>
          <size>0.02 0.04 0.04</size>
        </box>
      </geometry>
    </visual>
    <visual name="mono_cam/visual/lens">
      <pose>0.015 0 0 0 1.5707 0</pose>
      <geometry>
        <cylinder>
          <radius>0.008</radius>
          <length>0.01</length>
        </cylinder>
      </geometry>
    </visual>
    <visual name="mono_cam/visual/lens_glass">
      <pose>0.014 0 0 0 0 0</pose>
      <geometry>
        <sphere>
          <radius>0.0079</radius>
        </sphere>
      </geometry>
      <material name="default">
        <ambient>.4 .4 .5 .95</ambient>
        <diffuse>.4 .4 .5 .95</diffuse>
        <specular>1 1 1 1</specular>
        <emissive>0 0 0 1</emissive>
      </material>
    </visual>
    <sensor name="imager" type="camera">
      <pose>0 0 0 0 0 0</pose>
      <camera>
        <horizontal_fov>1.74</horizontal_fov>
        <image>
          <width>1280</width>
          <height>960</height>
        </image>
        <clip>
          <near>0.1</near>
          <far>3000</far>
        </clip>
      </camera>
      <always_on>1</always_on>
      <update_rate>30</update_rate>
      <visualize>true</visualize>
    </sensor>
    <gravity>true</gravity>
    <velocity_decay/>
  </link>
  <joint name="camera_joint" type="fixed">
    <parent link="base"/>
    <child link="camera_link"/>
    <origin xyz="0.0 0.0 0.025"/>
  </joint>
  <link name="gear_leg_left">
    <inertial>
      <mass value="0.1"/>
      <origin xyz="0 0 -0.05"/>
      <inertia ixx="0.0001" ixy="0" ixz="0" iyy="0.0001" iyz="0" izz="0.0001"/>
    </inertial>
    <visual>
      <origin xyz="0 0 -0.05"/>
      <geometry>
        <cylinder length="0.1" radius="0.01"/>
      </geometry>
    </visual>
    <collision>
      <origin xyz="0 0 -0.05"/>
      <geometry>
        <cylinder length="0.1" radius="0.01"/>
      </geometry>
    </collision>
  </link>
  <joint name="joint_gear_leg_left" type="fixed">
    <parent link="base"/>
    <child link="gear_leg_left"/>
    <origin xyz="0 0.05 0"/>
  </joint>
  <link name="gear_skid_left">
    <inertial>
      <mass value="0.1"/>
      <origin xyz="0 0 0"/>
      <inertia ixx="0.0001" ixy="0" ixz="0" iyy="0.0001" iyz="0" izz="0.0001"/>
    </inertial>
    <visual>
      <origin xyz="0 0 -0.1"/>
      <geometry>
        <box size="0.3 0.02 0.01"/>
      </geometry>
    </visual>
    <collision>
      <origin xyz="0 0 -0.1"/>
      <geometry>
        <box size="0.3 0.02 0.01"/>
      </geometry>
    </collision>
  </link>
  <joint name="joint_gear_skid_left" type="fixed">
    <parent link="gear_leg_left"/>
    <child link="gear_skid_left"/>
    <origin xyz="0 0 0"/>
  </joint>
  <link name="gear_leg_right">
    <inertial>
      <mass value="0.1"/>
      <origin xyz="0 0 -0.05"/>
      <inertia ixx="0.0001" ixy="0" ixz="0" iyy="0.0001" iyz="0" izz="0.0001"/>
    </inertial>
    <visual>
      <origin xyz="0 0 -0.05"/>
      <geometry>
        <cylinder length="0.1" radius="0.01"/>
      </geometry>
    </visual>
    <collision>
      <origin xyz="0 0 -0.05"/>
      <geometry>
        <cylinder length="0.1" radius="0.01"/>
      </geometry>
    </collision>
  </link>
  <joint name="joint_gear_leg_right" type="fixed">
    <parent link="base"/>
    <child link="gear_leg_right"/>
    <origin xyz="0 -0.05 0"/>
  </joint>
  <link name="gear_skid_right">
    <inertial>
      <mass value="0.1"/>
      <origin xyz="0 0 0"/>
      <inertia ixx="0.0001" ixy="0" ixz="0" iyy="0.0001" iyz="0" izz="0.0001"/>
    </inertial>
    <visual>
      <origin xyz="0 0 -0.1"/>
      <geometry>
        <box size="0.3 0.02 0.01"/>
      </geometry>
    </visual>
    <collision>
      <origin xyz="0 0 -0.1"/>
      <geometry>
        <box size="0.3 0.02 0.01"/>
      </geometry>
    </collision>
  </link>
  <joint name="joint_gear_skid_right" type="fixed">
    <parent link="gear_leg_right"/>
    <child link="gear_skid_right"/>
    <origin xyz="0 0 0"/>
  </joint>
  <link name="arm_1">
    <inertial>
      <mass value="0.16"/>
      <origin xyz="0.1145 0 0"/>
      <inertia ixx="0.000715213" ixy="0" ixz="0" iyy="0.000715213" iyz="0" izz="3.2e-05"/>
    </inertial>
    <visual>
      <origin rpy="0 1.5708 0" xyz="0 0 0"/>
      <geometry>
        <cylinder length="0.229" radius="0.02"/>
      </geometry>
    </visual>
    <collision>
      <origin rpy="0 1.5708 0" xyz="0 0 0"/>
      <geometry>
        <cylinder length="0.229" radius="0.02"/>
      </geometry>
    </collision>
  </link>
  <joint name="joint_arm_1" type="revolute">
    <parent link="base"/>
    <child link="arm_1"/>
    <origin rpy="0 0 0" xyz="0.1855 0 0"/>
    <axis xyz="1 0 0"/>
    <limit effort="5" lower="-1.57" upper="1.57" velocity="2.0"/>
  </joint>
  <link name="motor_1">
    <inertial>
      <mass value="0.088"/>
      <origin xyz="0 0 0"/>
      <inertia ixx="0.000112917" ixy="0" ixz="0" iyy="0.000112917" iyz="0" izz="6.25e-05"/>
    </inertial>
    <visual>
      <origin xyz="0 0 0"/>
      <geometry>
        <cylinder length="0.05" radius="0.02"/>
      </geometry>
    </visual>
    <collision>
      <origin xyz="0 0 0"/>
      <geometry>
        <cylinder length="0.05" radius="0.02"/>
      </geometry>
    </collision>
  </link>
  <joint name="joint_motor_1" type="fixed">
    <parent link="arm_1"/>
    <child link="motor_1"/>
    <origin xyz="0.0945 0 0.02"/>
  </joint>
  <link name="arm_2">
    <inertial>
      <mass value="0.16"/>
      <origin xyz="0.1145 0 0"/>
      <inertia ixx="0.000715213" ixy="0" ixz="0" iyy="0.000715213" iyz="0" izz="3.2e-05"/>
    </inertial>
    <visual>
      <origin rpy="0 1.5708 0" xyz="0 0 0"/>
      <geometry>
        <cylinder length="0.229" radius="0.02"/>
      </geometry>
    </visual>
    <collision>
      <origin rpy="0 1.5708 0" xyz="0 0 0"/>
      <geometry>
        <cylinder length="0.229" radius="0.02"/>
      </geometry>
    </collision>
  </link>
  <joint name="joint_arm_2" type="revolute">
    <parent link="base"/>
    <child link="arm_2"/>
    <origin rpy="0 0 1.047" xyz="0.09275 0.160643 0"/>
    <axis xyz="1 0 0"/>
    <limit effort="5" lower="-1.57" upper="1.57" velocity="2.0"/>
  </joint>
  <link name="motor_2">
    <inertial>
      <mass value="0.088"/>
      <origin xyz="0 0 0"/>
      <inertia ixx="0.000112917" ixy="0" ixz="0" iyy="0.000112917" iyz="0" izz="6.25e-05"/>
    </inertial>
    <visual>
      <origin xyz="0 0 0"/>
      <geometry>
        <cylinder length="0.05" radius="0.02"/>
      </geometry>
    </visual>
    <collision>
      <origin xyz="0 0 0"/>
      <geometry>
        <cylinder length="0.05" radius="0.02"/>
      </geometry>
    </collision>
  </link>
  <joint name="joint_motor_2" type="fixed">
    <parent link="arm_2"/>
    <child link="motor_2"/>
    <origin xyz="0.0945 0 0.02"/>
  </joint>
  <link name="arm_3">
    <inertial>
      <mass value="0.16"/>
      <origin xyz="0.1145 0 0"/>
      <inertia ixx="0.000715213" ixy="0" ixz="0" iyy="0.000715213" iyz="0" izz="3.2e-05"/>
    </inertial>
    <visual>
      <origin rpy="0 1.5708 0" xyz="0 0 0"/>
      <geometry>
        <cylinder length="0.229" radius="0.02"/>
      </geometry>
    </visual>
    <collision>
      <origin rpy="0 1.5708 0" xyz="0 0 0"/>
      <geometry>
        <cylinder length="0.229" radius="0.02"/>
      </geometry>
    </collision>
  </link>
  <joint name="joint_arm_3" type="revolute">
    <parent link="base"/>
    <child link="arm_3"/>
    <origin rpy="0 0 2.094" xyz="-0.09275 0.160643 0"/>
    <axis xyz="1 0 0"/>
    <limit effort="5" lower="-1.57" upper="1.57" velocity="2.0"/>
  </joint>
  <link name="motor_3">
    <inertial>
      <mass value="0.088"/>
      <origin xyz="0 0 0"/>
      <inertia ixx="0.000112917" ixy="0" ixz="0" iyy="0.000112917" iyz="0" izz="6.25e-05"/>
    </inertial>
    <visual>
      <origin xyz="0 0 0"/>
      <geometry>
        <cylinder length="0.05" radius="0.02"/>
      </geometry>
    </visual>
    <collision>
      <origin xyz="0 0 0"/>
      <geometry>
        <cylinder length="0.05" radius="0.02"/>
      </geometry>
    </collision>
  </link>
  <joint name="joint_motor_3" type="fixed">
    <parent link="arm_3"/>
    <child link="motor_3"/>
    <origin xyz="0.0945 0 0.02"/>
  </joint>
  <link name="arm_4">
    <inertial>
      <mass value="0.16"/>
      <origin xyz="0.1145 0 0"/>
      <inertia ixx="0.000715213" ixy="0" ixz="0" iyy="0.000715213" iyz="0" izz="3.2e-05"/>
    </inertial>
    <visual>
      <origin rpy="0 1.5708 0" xyz="0 0 0"/>
      <geometry>
        <cylinder length="0.229" radius="0.02"/>
      </geometry>
    </visual>
    <collision>
      <origin rpy="0 1.5708 0" xyz="0 0 0"/>
      <geometry>
        <cylinder length="0.229" radius="0.02"/>
      </geometry>
    </collision>
  </link>
  <joint name="joint_arm_4" type="revolute">
    <parent link="base"/>
    <child link="arm_4"/>
    <origin rpy="0 0 3.141" xyz="-0.1855 0 0"/>
    <axis xyz="1 0 0"/>
    <limit effort="5" lower="-1.57" upper="1.57" velocity="2.0"/>
  </joint>
  <link name="motor_4">
    <inertial>
      <mass value="0.088"/>
      <origin xyz="0 0 0"/>
      <inertia ixx="0.000112917" ixy="0" ixz="0" iyy="0.000112917" iyz="0" izz="6.25e-05"/>
    </inertial>
    <visual>
      <origin xyz="0 0 0"/>
      <geometry>
        <cylinder length="0.05" radius="0.02"/>
      </geometry>
    </visual>
    <collision>
      <origin xyz="0 0 0"/>
      <geometry>
        <cylinder length="0.05" radius="0.02"/>
      </geometry>
    </collision>
  </link>
  <joint name="joint_motor_4" type="fixed">
    <parent link="arm_4"/>
    <child link="motor_4"/>
    <origin xyz="0.0945 0 0.02"/>
  </joint>
  <link name="arm_5">
    <inertial>
      <mass value="0.16"/>
      <origin xyz="0.1145 0 0"/>
      <inertia ixx="0.000715213" ixy="0" ixz="0" iyy="0.000715213" iyz="0" izz="3.2e-05"/>
    </inertial>
    <visual>
      <origin rpy="0 1.5708 0" xyz="0 0 0"/>
      <geometry>
        <cylinder length="0.229" radius="0.02"/>
      </geometry>
    </visual>
    <collision>
      <origin rpy="0 1.5708 0" xyz="0 0 0"/>
      <geometry>
        <cylinder length="0.229" radius="0.02"/>
      </geometry>
    </collision>
  </link>
  <joint name="joint_arm_5" type="revolute">
    <parent link="base"/>
    <child link="arm_5"/>
    <origin rpy="0 0 4.188" xyz="-0.09275 -0.160643 0"/>
    <axis xyz="1 0 0"/>
    <limit effort="5" lower="-1.57" upper="1.57" velocity="2.0"/>
  </joint>
  <link name="motor_5">
    <inertial>
      <mass value="0.088"/>
      <origin xyz="0 0 0"/>
      <inertia ixx="0.000112917" ixy="0" ixz="0" iyy="0.000112917" iyz="0" izz="6.25e-05"/>
    </inertial>
    <visual>
      <origin xyz="0 0 0"/>
      <geometry>
        <cylinder length="0.05" radius="0.02"/>
      </geometry>
    </visual>
    <collision>
      <origin xyz="0 0 0"/>
      <geometry>
        <cylinder length="0.05" radius="0.02"/>
      </geometry>
    </collision>
  </link>
  <joint name="joint_motor_5" type="fixed">
    <parent link="arm_5"/>
    <child link="motor_5"/>
    <origin xyz="0.0945 0 0.02"/>
  </joint>
  <link name="arm_6">
    <inertial>
      <mass value="0.16"/>
      <origin xyz="0.1145 0 0"/>
      <inertia ixx="0.000715213" ixy="0" ixz="0" iyy="0.000715213" iyz="0" izz="3.2e-05"/>
    </inertial>
    <visual>
      <origin rpy="0 1.5708 0" xyz="0 0 0"/>
      <geometry>
        <cylinder length="0.229" radius="0.02"/>
      </geometry>
    </visual>
    <collision>
      <origin rpy="0 1.5708 0" xyz="0 0 0"/>
      <geometry>
        <cylinder length="0.229" radius="0.02"/>
      </geometry>
    </collision>
  </link>
  <joint name="joint_arm_6" type="revolute">
    <parent link="base"/>
    <child link="arm_6"/>
    <origin rpy="0 0 5.235" xyz="0.09275 -0.160643 0"/>
    <axis xyz="1 0 0"/>
    <limit effort="5" lower="-1.57" upper="1.57" velocity="2.0"/>
  </joint>
  <link name="motor_6">
    <inertial>
      <mass value="0.088"/>
      <origin xyz="0 0 0"/>
      <inertia ixx="0.000112917" ixy="0" ixz="0" iyy="0.000112917" iyz="0" izz="6.25e-05"/>
    </inertial>
    <visual>
      <origin xyz="0 0 0"/>
      <geometry>
        <cylinder length="0.05" radius="0.02"/>
      </geometry>
    </visual>
    <collision>
      <origin xyz="0 0 0"/>
      <geometry>
        <cylinder length="0.05" radius="0.02"/>
      </geometry>
    </collision>
  </link>
  <joint name="joint_motor_6" type="fixed">
    <parent link="arm_6"/>
    <child link="motor_6"/>
    <origin xyz="0.0945 0 0.02"/>
  </joint>
  <link name="prop_1">
    <inertial>
      <mass value="0.024"/>
      <origin xyz="0 0 0.02"/>
      <inertia ixx="4.25e-06" ixy="0" ixz="0" iyy="0.00010145" iyz="0" izz="0.0001053"/>
    </inertial>
    <visual>
      <origin xyz="0 0 0.02"/>
      <geometry>
        <box size="0.225 0.02 0.01"/>
      </geometry>
    </visual>
    <collision>
      <origin xyz="0 0 0.02"/>
      <geometry>
        <box size="0.225 0.02 0.01"/>
      </geometry>
    </collision>
  </link>
  <joint name="joint_prop_1" type="continuous">
    <parent link="motor_1"/>
    <child link="prop_1"/>
    <axis xyz="0 0 1"/>
  </joint>
  <link name="prop_2">
    <inertial>
      <mass value="0.024"/>
      <origin xyz="0 0 0.02"/>
      <inertia ixx="4.25e-06" ixy="0" ixz="0" iyy="0.00010145" iyz="0" izz="0.0001053"/>
    </inertial>
    <visual>
      <origin xyz="0 0 0.02"/>
      <geometry>
        <box size="0.225 0.02 0.01"/>
      </geometry>
    </visual>
    <collision>
      <origin xyz="0 0 0.02"/>
      <geometry>
        <box size="0.225 0.02 0.01"/>
      </geometry>
    </collision>
  </link>
  <joint name="joint_prop_2" type="continuous">
    <parent link="motor_2"/>
    <child link="prop_2"/>
    <axis xyz="0 0 1"/>
  </joint>
  <link name="prop_3">
    <inertial>
      <mass value="0.024"/>
      <origin xyz="0 0 0.02"/>
      <inertia ixx="4.25e-06" ixy="0" ixz="0" iyy="0.00010145" iyz="0" izz="0.0001053"/>
    </inertial>
    <visual>
      <origin xyz="0 0 0.02"/>
      <geometry>
        <box size="0.225 0.02 0.01"/>
      </geometry>
    </visual>
    <collision>
      <origin xyz="0 0 0.02"/>
      <geometry>
        <box size="0.225 0.02 0.01"/>
      </geometry>
    </collision>
  </link>
  <joint name="joint_prop_3" type="continuous">
    <parent link="motor_3"/>
    <child link="prop_3"/>
    <axis xyz="0 0 1"/>
  </joint>
  <link name="prop_4">
    <inertial>
      <mass value="0.024"/>
      <origin xyz="0 0 0.02"/>
      <inertia ixx="4.25e-06" ixy="0" ixz="0" iyy="0.00010145" iyz="0" izz="0.0001053"/>
    </inertial>
    <visual>
      <origin xyz="0 0 0.02"/>
      <geometry>
        <box size="0.225 0.02 0.01"/>
      </geometry>
    </visual>
    <collision>
      <origin xyz="0 0 0.02"/>
      <geometry>
        <box size="0.225 0.02 0.01"/>
      </geometry>
    </collision>
  </link>
  <joint name="joint_prop_4" type="continuous">
    <parent link="motor_4"/>
    <child link="prop_4"/>
    <axis xyz="0 0 1"/>
  </joint>
  <link name="prop_5">
    <inertial>
      <mass value="0.024"/>
      <origin xyz="0 0 0.02"/>
      <inertia ixx="4.25e-06" ixy="0" ixz="0" iyy="0.00010145" iyz="0" izz="0.0001053"/>
    </inertial>
    <visual>
      <origin xyz="0 0 0.02"/>
      <geometry>
        <box size="0.225 0.02 0.01"/>
      </geometry>
    </visual>
    <collision>
      <origin xyz="0 0 0.02"/>
      <geometry>
        <box size="0.225 0.02 0.01"/>
      </geometry>
    </collision>
  </link>
  <joint name="joint_prop_5" type="continuous">
    <parent link="motor_5"/>
    <child link="prop_5"/>
    <axis xyz="0 0 1"/>
  </joint>
  <link name="prop_6">
    <inertial>
      <mass value="0.024"/>
      <origin xyz="0 0 0.02"/>
      <inertia ixx="4.25e-06" ixy="0" ixz="0" iyy="0.00010145" iyz="0" izz="0.0001053"/>
    </inertial>
    <visual>
      <origin xyz="0 0 0.02"/>
      <geometry>
        <box size="0.225 0.02 0.01"/>
      </geometry>
    </visual>
    <collision>
      <origin xyz="0 0 0.02"/>
      <geometry>
        <box size="0.225 0.02 0.01"/>
      </geometry>
    </collision>
  </link>
  <joint name="joint_prop_6" type="continuous">
    <parent link="motor_6"/>
    <child link="prop_6"/>
    <axis xyz="0 0 1"/>
  </joint>
  <!-- Pluggins -->
  <!-- Pose Publisher Plugin -->
  <plugin filename="ignition-gazebo-pose-publisher-system" name="ignition::gazebo::systems::PosePublisher">
    <publish_link_pose>true</publish_link_pose>
    <publish_sensor_pose>true</publish_sensor_pose>
    <publish_collision_pose>false</publish_collision_pose>
    <publish_visual_pose>false</publish_visual_pose>
    <publish_nested_model_pose>true</publish_nested_model_pose>
    <publish_model_pose>false</publish_model_pose>
    <use_pose_vector_msg>true</use_pose_vector_msg>
    <static_publisher>true</static_publisher>
    <static_update_frequency>100</static_update_frequency>
  </plugin>
  <!-- Joint states plugin -->
  <plugin filename="ignition-gazebo-joint-state-publisher-system" name="ignition::gazebo::systems::JointStatePublisher">
    <robotNamespace>/model/variable_tilt_hexacopter</robotNamespace>
  </plugin>
  <!-- Odometry Plugin -->
  <plugin filename="ignition-gazebo-odometry-publisher-system" name="ignition::gazebo::systems::OdometryPublisher">
    <dimensions>3</dimensions>
    <odom_publish_frequency>100</odom_publish_frequency>
  </plugin>
  <!-- ========== Sub-macros ========== -->
  <!-- ========== Plugin Instantiations ========== -->
  <plugin filename="libignition-gazebo-multicopter-motor-model-system" name="ignition::gazebo::systems::MulticopterMotorModel">
    <robotNamespace>/model/variable_tilt_hexacopter</robotNamespace>
    <jointName>joint_prop_1</jointName>
    <linkName>prop_1</linkName>
    <turningDirection>ccw</turningDirection>
    <timeConstantUp>0.0125</timeConstantUp>
    <timeConstantDown>0.025</timeConstantDown>
    <maxRotVelocity>1000.0</maxRotVelocity>
    <motorConstant>8.54858e-06</motorConstant>
    <momentConstant>0.016</momentConstant>
    <commandSubTopic>command/motor_speed</commandSubTopic>
    <motorNumber>0</motorNumber>
    <rotorDragCoefficient>8.06428e-05</rotorDragCoefficient>
    <rollingMomentCoefficient>1e-06</rollingMomentCoefficient>
    <motorSpeedPubTopic>motor_speed/0</motorSpeedPubTopic>
    <rotorVelocitySlowdownSim>10</rotorVelocitySlowdownSim>
    <motorType>velocity</motorType>
  </plugin>
  <plugin filename="libignition-gazebo-multicopter-motor-model-system" name="ignition::gazebo::systems::MulticopterMotorModel">
    <robotNamespace>/model/variable_tilt_hexacopter</robotNamespace>
    <jointName>joint_prop_2</jointName>
    <linkName>prop_2</linkName>
    <turningDirection>cw</turningDirection>
    <timeConstantUp>0.0125</timeConstantUp>
    <timeConstantDown>0.025</timeConstantDown>
    <maxRotVelocity>1000.0</maxRotVelocity>
    <motorConstant>8.54858e-06</motorConstant>
    <momentConstant>0.016</momentConstant>
    <commandSubTopic>command/motor_speed</commandSubTopic>
    <motorNumber>1</motorNumber>
    <rotorDragCoefficient>8.06428e-05</rotorDragCoefficient>
    <rollingMomentCoefficient>1e-06</rollingMomentCoefficient>
    <motorSpeedPubTopic>motor_speed/1</motorSpeedPubTopic>
    <rotorVelocitySlowdownSim>10</rotorVelocitySlowdownSim>
    <motorType>velocity</motorType>
  </plugin>
  <plugin filename="libignition-gazebo-multicopter-motor-model-system" name="ignition::gazebo::systems::MulticopterMotorModel">
    <robotNamespace>/model/variable_tilt_hexacopter</robotNamespace>
    <jointName>joint_prop_3</jointName>
    <linkName>prop_3</linkName>
    <turningDirection>ccw</turningDirection>
    <timeConstantUp>0.0125</timeConstantUp>
    <timeConstantDown>0.025</timeConstantDown>
    <maxRotVelocity>1000.0</maxRotVelocity>
    <motorConstant>8.54858e-06</motorConstant>
    <momentConstant>0.016</momentConstant>
    <commandSubTopic>command/motor_speed</commandSubTopic>
    <motorNumber>2</motorNumber>
    <rotorDragCoefficient>8.06428e-05</rotorDragCoefficient>
    <rollingMomentCoefficient>1e-06</rollingMomentCoefficient>
    <motorSpeedPubTopic>motor_speed/2</motorSpeedPubTopic>
    <rotorVelocitySlowdownSim>10</rotorVelocitySlowdownSim>
    <motorType>velocity</motorType>
  </plugin>
  <plugin filename="libignition-gazebo-multicopter-motor-model-system" name="ignition::gazebo::systems::MulticopterMotorModel">
    <robotNamespace>/model/variable_tilt_hexacopter</robotNamespace>
    <jointName>joint_prop_4</jointName>
    <linkName>prop_4</linkName>
    <turningDirection>cw</turningDirection>
    <timeConstantUp>0.0125</timeConstantUp>
    <timeConstantDown>0.025</timeConstantDown>
    <maxRotVelocity>1000.0</maxRotVelocity>
    <motorConstant>8.54858e-06</motorConstant>
    <momentConstant>0.016</momentConstant>
    <commandSubTopic>command/motor_speed</commandSubTopic>
    <motorNumber>3</motorNumber>
    <rotorDragCoefficient>8.06428e-05</rotorDragCoefficient>
    <rollingMomentCoefficient>1e-06</rollingMomentCoefficient>
    <motorSpeedPubTopic>motor_speed/3</motorSpeedPubTopic>
    <rotorVelocitySlowdownSim>10</rotorVelocitySlowdownSim>
    <motorType>velocity</motorType>
  </plugin>
  <plugin filename="libignition-gazebo-multicopter-motor-model-system" name="ignition::gazebo::systems::MulticopterMotorModel">
    <robotNamespace>/model/variable_tilt_hexacopter</robotNamespace>
    <jointName>joint_prop_5</jointName>
    <linkName>prop_5</linkName>
    <turningDirection>ccw</turningDirection>
    <timeConstantUp>0.0125</timeConstantUp>
    <timeConstantDown>0.025</timeConstantDown>
    <maxRotVelocity>1000.0</maxRotVelocity>
    <motorConstant>8.54858e-06</motorConstant>
    <momentConstant>0.016</momentConstant>
    <commandSubTopic>command/motor_speed</commandSubTopic>
    <motorNumber>4</motorNumber>
    <rotorDragCoefficient>8.06428e-05</rotorDragCoefficient>
    <rollingMomentCoefficient>1e-06</rollingMomentCoefficient>
    <motorSpeedPubTopic>motor_speed/4</motorSpeedPubTopic>
    <rotorVelocitySlowdownSim>10</rotorVelocitySlowdownSim>
    <motorType>velocity</motorType>
  </plugin>
  <plugin filename="libignition-gazebo-multicopter-motor-model-system" name="ignition::gazebo::systems::MulticopterMotorModel">
    <robotNamespace>/model/variable_tilt_hexacopter</robotNamespace>
    <jointName>joint_prop_6</jointName>
    <linkName>prop_6</linkName>
    <turningDirection>cw</turningDirection>
    <timeConstantUp>0.0125</timeConstantUp>
    <timeConstantDown>0.025</timeConstantDown>
    <maxRotVelocity>1000.0</maxRotVelocity>
    <motorConstant>8.54858e-06</motorConstant>
    <momentConstant>0.016</momentConstant>
    <commandSubTopic>command/motor_speed</commandSubTopic>
    <motorNumber>5</motorNumber>
    <rotorDragCoefficient>8.06428e-05</rotorDragCoefficient>
    <rollingMomentCoefficient>1e-06</rollingMomentCoefficient>
    <motorSpeedPubTopic>motor_speed/5</motorSpeedPubTopic>
    <rotorVelocitySlowdownSim>10</rotorVelocitySlowdownSim>
    <motorType>velocity</motorType>
  </plugin>
  <plugin filename="libignition-gazebo-joint-position-controller-system" name="ignition::gazebo::systems::JointPositionController">
    <joint_name>joint_arm_1</joint_name>
    <topic>/model/variable_tilt_hexacopter/joint_arm_1/cmd_pos</topic>
  </plugin>
  <plugin filename="libignition-gazebo-joint-position-controller-system" name="ignition::gazebo::systems::JointPositionController">
    <joint_name>joint_arm_2</joint_name>
    <topic>/model/variable_tilt_hexacopter/joint_arm_2/cmd_pos</topic>
  </plugin>
  <plugin filename="libignition-gazebo-joint-position-controller-system" name="ignition::gazebo::systems::JointPositionController">
    <joint_name>joint_arm_3</joint_name>
    <topic>/model/variable_tilt_hexacopter/joint_arm_3/cmd_pos</topic>
  </plugin>
  <plugin filename="libignition-gazebo-joint-position-controller-system" name="ignition::gazebo::systems::JointPositionController">
    <joint_name>joint_arm_4</joint_name>
    <topic>/model/variable_tilt_hexacopter/joint_arm_4/cmd_pos</topic>
  </plugin>
  <plugin filename="libignition-gazebo-joint-position-controller-system" name="ignition::gazebo::systems::JointPositionController">
    <joint_name>joint_arm_5</joint_name>
    <topic>/model/variable_tilt_hexacopter/joint_arm_5/cmd_pos</topic>
  </plugin>
  <plugin filename="libignition-gazebo-joint-position-controller-system" name="ignition::gazebo::systems::JointPositionController">
    <joint_name>joint_arm_6</joint_name>
    <topic>/model/variable_tilt_hexacopter/joint_arm_6/cmd_pos</topic>
  </plugin>
</robot>
